<?xml version="1.0" ?>
<!-- =================================================================================== -->
<!-- |    This document was autogenerated by xacro from /Users/mikaeltrana/Development/Robots/Learning/cart_pole/install/robot_description/share/robot_description/robot/cart_pole.urdf.xacro | -->
<!-- |    EDITING THIS FILE BY HAND IS NOT RECOMMENDED                                 | -->
<!-- =================================================================================== -->
<robot name="cart_pole">
  <!-- =============== Link & Joint =============== -->
  <!-- Base -->
  <link name="base_footprint"/>
  <joint name="base_link_joint" type="fixed">
    <origin xyz="0 0 0"/>
    <parent link="base_footprint"/>
    <child link="base_link"/>
  </joint>
  <link name="base_link">
    <visual>
      <geometry>
        <mesh filename="package://robot_description/meshes/DAE/base/stand.dae"/>
      </geometry>
    </visual>
    <collision>
      <geometry>
        <mesh filename="package://robot_description/meshes/STL/base/stand.stl"/>
      </geometry>
    </collision>
    <inertial>
      <origin xyz="0 0 -0.333"/>
      <mass value="488"/>
      <inertia ixx="14.25" ixy="0" ixz="0.0245" iyy="78.78" iyz="0" izz="64.57"/>
    </inertial>
  </link>
  <joint name="cart_joint" type="prismatic">
    <origin rpy="0 0 0" xyz="0 0 0"/>
    <parent link="base_link"/>
    <child link="cart_link"/>
    <limit effort="30" lower="-1.0" upper="1.0" velocity="10"/>
    <dynamics damping="0.005" friction="0.1"/>
    <axis xyz="1 0 0"/>
  </joint>
  <link name="cart_link">
    <visual>
      <geometry>
        <mesh filename="package://robot_description/meshes/DAE/cart/cart.dae"/>
      </geometry>
    </visual>
    <collision>
      <geometry>
        <mesh filename="package://robot_description/meshes/STL/cart/cart.stl"/>
      </geometry>
    </collision>
    <inertial>
      <origin xyz="0 0 0"/>
      <mass value="2.7"/>
      <inertia ixx="0.005878" ixy="0" ixz="0" iyy="0.01145" iyz="0" izz="0.01186"/>
    </inertial>
    <surface>
      <friction>
        <ode>
          <mu>0.8</mu>
          <mu2>0.8</mu2>
          <kp>1e15</kp>
          <kd>1e13</kd>
        </ode>
      </friction>
      <bounce>
        <restitution_coefficient>0.01</restitution_coefficient>
        <threshold>10</threshold>
      </bounce>
      <contact>
        <ode>
          <max_vel>0.01</max_vel>
          <minDepth>0</minDepth>
          <contact_surface_layer>0</contact_surface_layer>
        </ode>
      </contact>
    </surface>
  </link>
  <joint name="pole_joint" type="revolute">
    <origin rpy="0 3.14159274 0" xyz="0 0.1 0"/>
    <parent link="cart_link"/>
    <child link="pole_link"/>
    <limit effort="15" lower="-1.7" upper="1.7" velocity="10"/>
    <!-- <dynamics damping="0.1" friction="0.01"/> -->
    <axis xyz="0 1 0"/>
  </joint>
  <link name="pole_link">
    <visual>
      <geometry>
        <mesh filename="package://robot_description/meshes/DAE/pole/pole.dae"/>
      </geometry>
    </visual>
    <collision>
      <geometry>
        <mesh filename="package://robot_description/meshes/STL/pole/pole.stl"/>
      </geometry>
    </collision>
    <inertial>
      <origin xyz="0 0 -0.489554"/>
      <mass value="0.85955"/>
      <inertia ixx="0.07508" ixy="0" ixz="-0.0000095" iyy="0.07574" iyz="0" izz="0.0007851"/>
    </inertial>
  </link>
  <joint name="tip_joint" type="revolute">
    <origin rpy="0 0 0" xyz="0 0 -1"/>
    <parent link="pole_link"/>
    <child link="tip_link"/>
    <limit effort="30" lower="-1.0" upper="1.0" velocity="10"/>
    <!-- <dynamics damping="0.005" friction="0.1"/>  -->
    <axis xyz="0 1 0"/>
  </joint>
  <link name="tip_link">
    <inertial>
      <origin xyz="0 0 0"/>
      <mass value="0.3"/>
      <inertia ixx="0.00000001" ixy="0" ixz="0" iyy="0.00000001" iyz="0" izz="0.00000001"/>
    </inertial>
  </link>
  <transmission name="cart_trans">
    <type>transmission_interface/SimpleTransmission</type>
    <joint name="cart_joint">
      <hardwareInterface>hardware_interface/EffortJointInterface</hardwareInterface>
    </joint>
    <actuator name="cart_motor">
      <hardwareInterface>hardware_interface/EffortJointInterface</hardwareInterface>
      <mechanicalReduction>1</mechanicalReduction>
    </actuator>
  </transmission>
  <!-- =============== Gazebo =============== -->
  <gazebo>
    <plugin filename="libmodel_reset_plugin.dylib" name="reinforcement_learning::ModelResetPlugin"/>
    <plugin filename="libgz_ros2_control-system.dylib" name="gz_ros2_control::GazeboSimROS2ControlPlugin">
      <parameters>/Users/mikaeltrana/Development/Robots/Learning/cart_pole/install/robot_control/share/robot_control/config/controller.yaml</parameters>
    </plugin>
    <plugin filename="gz-sim-pose-publisher-system" name="gz::sim::systems::PosePublisher">
      <update_frequency>800</update_frequency>
      <publish_link_pose>true</publish_link_pose>
      <use_pose_vector_msg>true</use_pose_vector_msg>
      <publish_nested_model_pose>true</publish_nested_model_pose>
    </plugin>
  </gazebo>
  <ros2_control name="fws" type="system">
    <hardware>
      <plugin>gz_ros2_control/GazeboSimSystem</plugin>
    </hardware>
    <joint name="cart_joint">
      <!-- <command_interface name="velocity">
        <param name="min">-200</param>
        <param name="max">200</param>
      </command_interface> -->
      <command_interface name="position">
      </command_interface>
      <state_interface name="position"/>
      <state_interface name="velocity"/>
      <state_interface name="effort"/>
    </joint>
    <!-- <joint name="pole_joint">
      <state_interface name="position"/>
      <state_interface name="velocity"/>
      <state_interface name="effort"/>
    </joint>      -->
  </ros2_control>
  <gazebo reference="base_link">
    <selfCollide>false</selfCollide>
    <mu1 value="0.05"/>
    <mu2 value="0.05"/>
  </gazebo>
  <gazebo reference="cart_link">
    <selfCollide>false</selfCollide>
    <mu1 value="1.2"/>
    <mu2 value="1.2"/>
  </gazebo>
  <gazebo reference="pole_link">
    <selfCollide>false</selfCollide>
    <mu1 value="1"/>
    <mu2 value="0"/>
  </gazebo>
  <gazebo reference="tip_link">
    <selfCollide>false</selfCollide>
    <mu1 value="1.2"/>
    <mu2 value="1.2"/>
  </gazebo>
</robot>
